Workbook

Sheet מבוא ומתודולוגיה
A1: תחזית נטל המס לפי חמישוני הכנסה, לאור השינוי הצפוי בהרכב האוכלוסייה
A2: מודל: כמה יורדת הכנסת המדינה ממס הכנסה אם הרכב האוכלוסייה משתנה כצפוי — וכמה צריך להעלות את הנטל כדי לשמור על אותה הכנסה
A4: שאלת המחקר
A5: היום נטל מס ההכנסה בישראל מוטל בעיקר על החמישון העליון. האוכלוסייה החרדית מרוכזת בחמישוני ההכנסה התחתונים ומשלמת מס הכנסה נמוך יחסית; היהודים הלא-חרדים, המרוכזים יחסית בחמישונים העליונים, נושאים בעיקר הנטל. לפי תחזיות האוכלוסייה, חלקם היחסי של החרדים באוכלוסייה צפוי לגדול משמעותית וחלקם של היהודים הלא-חרדים לרדת. המודל בודק: אם 'מקפיאים' את פרופיל ההכנסה/מס של כל קבוצה כפי שהוא היום (2022), ורק 'מתקדמים' עם האוכלוסייה לפי התחזית הדמוגרפית - כמה תרד הכנסת המדינה ממס הכנסה, וכמה צריך להעלות את הנטל (בעיקר על החמישונים העליונים) כדי לגייס את אותה הכנסה כמו היום.
A7: הנחות המפתח של המודל
A8: 1. ההתפלגות הפנימית של כל קבוצת אוכלוסייה (יהודים לא-חרדים / חרדים / ערבים) על פני 5 חמישוני ההכנסה הכלליים (הארציים) נשארת קבועה כפי שנמדדה ב-2022. כלומר, לא מניחים ששיעור החרדים בחמישון התחתון ישתנה — רק שמספר משקי הבית החרדים בכללותו גדל.
A9: 2. תשלום המס הממוצע למשק בית בכל תא (קבוצה × חמישון) נשאר קבוע בערכי 2022 (ריאלית, ללא אינפלציה/שינויי מדיניות).
A10: 3. סך משקי הבית גדל עם הזמן לפי קצב הגידול הדמוגרפי של הלמ"ס (ולא נשאר קבוע) — וגם התמהיל בין הקבוצות משתנה, שני האפקטים ביחד. קצב גידול משקי הבית מקורב לקצב גידול האוכלוסייה הכללי (ראו הסתייגות בגיליון 'תחזית הרכב אוכלוסייה').
A11: 4. הבסיס לחישוב הוא מס הכנסה ורווחי הון בלבד (התואם את צילומי המסך שסופקו ואת הטענה המקורית על 80% מהנטל) — לא כלל תשלומי המסים (מע"מ, ביטוח לאומי, מיסי נדל"ן וכו').
A13: חשוב: איך מודדים 'ירידה בהכנסה' על פני 43 שנה של צמיחה דמוגרפית
A14: כי האוכלוסייה עצמה גדלה (לא רק משנה תמהיל), ההכנסה הכוללת בערכים נומינליים דווקא *עולה* עם השנים — יש יותר משקי בית ששולמים מס, גם אם כל אחד מהם משלם בממוצע פחות. השוואה נאיבית מול סך ההכנסה הנומינלית של 2022 בלבד מטעה: היא מראה שאין צורך להעלות מיסים כלל, כי הצמיחה הדמוגרפית 'מכסה' על שינוי התמהיל.
A15: לכן ההשוואה המרכזית בקובץ הזה (בגיליונות 'פירוט תרחיש ריאלי 2065' ו'השוואת תרחישים') היא בין הנטל הממוצע למשק בית (לא הסכום הכולל): כמה בממוצע ישלם משק בית ב-2065 לעומת כמה שילם משק בית ממוצע ב-2022. זהו מדד שמנוטרל לחלוטין מגידול האוכלוסייה, ומבודד את האפקט הטהור של שינוי התמהיל בין הקבוצות — בדיוק השאלה שביקשת לבדוק. הפער הזה (בניגוד להשוואה הנומינלית) שלילי ועקבי לאורך זמן, וממנו נגזר כמה צריך להעלות את הנטל על החמישונים העליונים כדי לשמור על אותו נטל מס ממוצע למשק בית כמו היום. ההשוואה הנומינלית עדיין מוצגת בקובץ, לשם הקשר בלבד, אך אינה הבסיס לחישובי ה'העלאה הנדרשת'.
... A29: תאי קלט (מספרים כחולים) ניתנים לעריכה — כל שאר התאים הם נוסחאות שמתעדכנות אוטומטית.

Sheet בסיס 2022
A1: נתוני בסיס 2022 — מס הכנסה ורווחי הון, לפי קבוצת אוכלוסייה וחמישון הכנסה כללי
A2: מקור: מצגת 'מאזן פיסקלי מלא' (שקפים 74-75) + צילומי המסך שסופקו
A4: מספר משקי בית (אלפים), 2022
A5: קבוצת אוכלוסייה | B5: חמישון 1 | C5: חמישון 2 | D5: חמישון 3 | E5: חמישון 4 | F5: חמישון 5 | G5: סה"כ
A6: יהודים לא חרדים | B6: 248 | C6: 365 | D6: 461 | E6: 523 | F6: 555 | G6: =SUM(B6:F6)
A7: חרדים | B7: 98 | C7: 58 | D7: 27 | E7: 18 | F7: 8 | G7: =SUM(B7:F7)
A8: ערבים | B8: 216 | C8: 126 | D8: 71 | E8: 30 | F8: 10 | G8: =SUM(B8:F8)
A9: סה"כ | B9: =SUM(B6:B8) | C9: =SUM(C6:C8) | D9: =SUM(D6:D8) | E9: =SUM(E6:E8) | F9: =SUM(F6:F8) | G9: =SUM(G6:G8)
A11: תשלום מס הכנסה+רווחי הון חודשי ממוצע למשק בית (₪), 2022
A12: קבוצת אוכלוסייה | B12: חמישון 1 | C12: חמישון 2 | D12: חמישון 3 | E12: חמישון 4 | F12: חמישון 5
A13: יהודים לא חרדים | B13: 78.71 | C13: 483.76 | D13: 1493.29 | E13: 3632.97 | F13: 12383.56
A14: חרדים | B14: 42.3 | C14: 642.68 | D14: 1924.58 | E14: 4350.3 | F14: 7515.45
A15: ערבים | B15: 162.33 | C15: 590.46 | D15: 2243.59 | E15: 4275.56 | F15: 14438.37
A17: הכנסת מדינה חודשית ממס הכנסה+רווחי הון (₪) = משקי"ב (אלפים) × 1,000 × מס ממוצע
A18: קבוצת אוכלוסייה | B18: חמישון 1 | C18: חמישון 2 | D18: חמישון 3 | E18: חמישון 4 | F18: חמישון 5 | G18: סה"כ
A19: יהודים לא חרדים | B19: =B6*1000*B13 | C19: =C6*1000*C13 | D19: =D6*1000*D13 | E19: =E6*1000*E13 | F19: =F6*1000*F13 | G19: =SUM(B19:F19)
A20: חרדים | B20: =B7*1000*B14 | C20: =C7*1000*C14 | D20: =D7*1000*D14 | E20: =E7*1000*E14 | F20: =F7*1000*F14 | G20: =SUM(B20:F20)
A21: ערבים | B21: =B8*1000*B15 | C21: =C8*1000*C15 | D21: =D8*1000*D15 | E21: =E8*1000*E15 | F21: =F8*1000*F15 | G21: =SUM(B21:F21)
A22: סה"כ | B22: =SUM(B19:B21) | C22: =SUM(C19:C21) | D22: =SUM(D19:D21) | E22: =SUM(E19:E21) | F22: =SUM(F19:F21) | G22: =SUM(G19:G21)
A24: התפלגות פנימית של כל קבוצה על פני 5 החמישונים הכלליים (קבוע — משמש לתחזית)
A25: קבוצת אוכלוסייה | B25: חמישון 1 | C25: חמישון 2 | D25: חמישון 3 | E25: חמישון 4 | F25: חמישון 5
A26: יהודים לא חרדים | B26: =B6/$G6 | C26: =C6/$G6 | D26: =D6/$G6 | E26: =E6/$G6 | F26: =F6/$G6
A27: חרדים | B27: =B7/$G7 | C27: =C7/$G7 | D27: =D7/$G7 | E27: =E7/$G7 | F27: =F7/$G7
A28: ערבים | B28: =B8/$G8 | C28: =C8/$G8 | D28: =D8/$G8 | E28: =E8/$G8 | F28: =F8/$G8
A30: התפלגות נטל מס ההכנסה בין החמישונים, 2022 (הגרסה בפועל, מנתוני 2022, לטענת "80% מהמס")
B31: חמישון 1 | C31: חמישון 2 | D31: חמישון 3 | E31: חמישון 4 | F31: חמישון 5
A32: חלק מהכנסות המדינה ממס הכנסה | B32: =B22/$G$22 | C32: =C22/$G$22 | D32: =D22/$G$22 | E32: =E22/$G$22 | F32: =F22/$G$22
A34: שימו לב: לפי נתוני הסקר (מס הכנסה+רווחי הון בלבד, ברמת משק הבית) החמישון העליון נושא כ-68% מהנטל ב-2022 — לא 80%. פער זה נובע ככל הנראה מהבדל בשיטת המדידה של הטענה המקורית (למשל: עשירונים/פרטים במקום חמישונים/משקי בית, או מקור נתונים אחר של רשות המסים).
A37: מס הכנסה ממוצע משוקלל למשק בית מכלל הקבוצה (₪, 2022) — עוזר לחישובי התחזית
A38: קבוצת אוכלוסייה | B38: ממוצע כללי (כל 5 החמישונים) | C38: ממוצע הנובע מחמישון 5 בלבד
A39: יהודים לא חרדים | B39: =G19/(G6*1000) | C39: =F19/(G6*1000)
A40: חרדים | B40: =G20/(G7*1000) | C40: =F20/(G7*1000)
A41: ערבים | B41: =G21/(G8*1000) | C41: =F21/(G8*1000)
A43: מס הכנסה ממוצע למשק בית, כלל האוכלוסייה, 2022 (₪ לחודש) — נטל הבסיס שאליו משווים כל תחזית
A44: ממוצע כלל-ארצי, 2022 | B44: =G22/(G9*1000)

Sheet תחזית הרכב אוכלוסייה
A1: תחזית הרכב האוכלוסייה, 3 תרחישים
A2: מקור: מצגת "מאזן פיסקלי מלא" (שקף 8), על בסיס תחזית הלמ"ס
A4: שיעור כל קבוצה מסך משקי הבית/האוכלוסייה, לפי תרחיש ושנה
A5: תרחיש | B5: שנה | C5: יהודים לא חרדים | D5: ערבים | E5: חרדים
A6: גבוה | B6: 2022 | C6: 0.67 | D6: 0.21 | E6: 0.12
A7: גבוה | B7: 2025 | C7: 0.64 | D7: 0.21 | E7: 0.15
A8: גבוה | B8: 2035 | C8: 0.6 | D8: 0.21 | E8: 0.19
A9: גבוה | B9: 2045 | C9: 0.56 | D9: 0.2 | E9: 0.24
A10: גבוה | B10: 2055 | C10: 0.51 | D10: 0.19 | E10: 0.3
A11: גבוה | B11: 2065 | C11: 0.45 | D11: 0.18 | E11: 0.37
A13: ריאלי | B13: 2022 | C13: 0.67 | D13: 0.21 | E13: 0.12
A14: ריאלי | B14: 2025 | C14: 0.64 | D14: 0.21 | E14: 0.15
A15: ריאלי | B15: 2035 | C15: 0.61 | D15: 0.21 | E15: 0.18
A16: ריאלי | B16: 2045 | C16: 0.57 | D16: 0.21 | E16: 0.22
A17: ריאלי | B17: 2055 | C17: 0.53 | D17: 0.2 | E17: 0.27
A18: ריאלי | B18: 2065 | C18: 0.48 | D18: 0.2 | E18: 0.32
... A25: נמוך | B25: 2065 | C25: 0.53 | D25: 0.2 | E25: 0.27
A27: הנחות קצב גידול אוכלוסייה שנתי, לפי תרחיש ותקופה (מקור: תחזית הלמ"ס 2015-2065, קירוב מתועד)
A28: תרחיש | B28: תקופה | C28: קצב שנתי | D28: מס' שנים בתקופה
A30: גבוה | B30: 2022-2045 | C30: 0.021 | D30: 23
A31: גבוה | B31: 2046-2055 | C31: 0.023 | D31: 10
A32: גבוה | B32: 2056-2065 | C32: 0.024 | D32: 10
A34: ריאלי | B34: 2022-2025 | C34: 0.019 | D34: 3
A35: ריאלי | B35: 2026-2035 | C35: 0.018 | D35: 10
A36: ריאלי | B36: 2036-2055 | C36: 0.017 | D36: 20
A37: ריאלי | B37: 2056-2065 | C37: 0.016 | D37: 10
A39: נמוך | B39: 2022-2025 | C39: 0.017 | D39: 3
A40: נמוך | B40: 2026-2035 | C40: 0.014 | D40: 10
A41: נמוך | B41: 2036-2045 | C41: 0.013 | D41: 10
A42: נמוך | B42: 2046-2055 | C42: 0.01 | D42: 10
A43: נמוך | B43: 2056-2065 | C43: 0.008 | D43: 10
A46: מדד גידול מספר משקי הבית (יחסית ל-2022=1.00), לפי תרחיש ושנה — מבוסס על הקצבים לעיל
A47: תרחיש | B47: 2022 | C47: 2025 | D47: 2035 | E47: 2045 | F47: 2055 | G47: 2065
A48: גבוה | B48: 1 | C48: =B48*(1+$C$30)^3 | D48: =C48*(1+$C$30)^10 | E48: =D48*(1+$C$30)^10 | F48: =E48*(1+$C$31)^$D$31 | G48: =F48*(1+$C$32)^$D$32
A49: ריאלי | B49: 1 | C49: =B49*(1+$C$34)^$D$34 | D49: =C49*(1+$C$35)^$D$35 | E49: =D49*(1+$C$36)^10 | F49: =E49*(1+$C$36)^10 | G49: =F49*(1+$C$37)^$D$37
A50: נמוך | B50: 1 | C50: =B50*(1+$C$39)^$D$39 | D50: =C50*(1+$C$40)^$D$40 | E50: =D50*(1+$C$41)^$D$41 | F50: =E50*(1+$C$42)^$D$42 | G50: =F50*(1+$C$43)^$D$43
A52: הסתייגות: קצב גידול משקי הבית מקורב כאן לקצב גידול האוכלוסייה הכללי, ואינו מתקן להבדלי גודל משק בית בין הקבוצות (גודל משק בית חרדי גדול משמעותית מהממוצע). זהו קירוב סביר לכיוון השינוי ולסדר הגודל שלו, לא תחזית מדויקת של מספר משקי הבית העתידי.

Sheet פירוט תרחיש ריאלי 2065
A1: פירוט מלא: תרחיש ריאלי (תרחיש הביניים), שנת 2065
A2: כל הערכים בעמודה זו מחושבים אוטומטית מהגיליונות 'בסיס 2022' ו'תחזית הרכב אוכלוסייה'
A4: מדד גידול מספר משקי הבית עד 2065 (יחסית ל-2022=1.00) | B4: ='תחזית הרכב אוכלוסייה'!G49
A5: סה"כ משקי בית, 2022 (אלפים) | B5: ='בסיס 2022'!G9
A6: סה"כ משקי בית, 2065 (אלפים) — לפי מדד הגידול | B6: =B5*B4
A7: חלק יהודים לא-חרדים באוכלוסייה, 2065 (תרחיש ריאלי) | B7: ='תחזית הרכב אוכלוסייה'!C18
A8: חלק חרדים באוכלוסייה, 2065 (תרחיש ריאלי) | B8: ='תחזית הרכב אוכלוסייה'!E18
A9: חלק ערבים באוכלוסייה, 2065 (תרחיש ריאלי) | B9: ='תחזית הרכב אוכלוסייה'!D18
A11: משקי בית עתידיים לפי קבוצה, 2065 (אלפים)
B12: יהודים לא חרדים | C12: חרדים | D12: ערבים
A13: סה"כ | B13: =$B$6*B7 | C13: =$B$6*B8 | D13: =$B$6*B9
A15: משקי בית עתידיים לפי קבוצה וחמישון, 2065 (אלפים) — לפי ההתפלגות הפנימית הקבועה מ-2022
A16: קבוצת אוכלוסייה | B16: חמישון 1 | C16: חמישון 2 | D16: חמישון 3 | E16: חמישון 4 | F16: חמישון 5 | G16: סה"כ
A17: יהודים לא חרדים | B17: =$B$13*'בסיס 2022'!B26 | C17: =$B$13*'בסיס 2022'!C26 | D17: =$B$13*'בסיס 2022'!D26 | E17: =$B$13*'בסיס 2022'!E26 | F17: =$B$13*'בסיס 2022'!F26 | G17: =SUM(B17:F17)
A18: חרדים | B18: =$C$13*'בסיס 2022'!B27 | C18: =$C$13*'בסיס 2022'!C27 | D18: =$C$13*'בסיס 2022'!D27 | E18: =$C$13*'בסיס 2022'!E27 | F18: =$C$13*'בסיס 2022'!F27 | G18: =SUM(B18:F18)
A19: ערבים | B19: =$D$13*'בסיס 2022'!B28 | C19: =$D$13*'בסיס 2022'!C28 | D19: =$D$13*'בסיס 2022'!D28 | E19: =$D$13*'בסיס 2022'!E28 | F19: =$D$13*'בסיס 2022'!F28 | G19: =SUM(B19:F19)
A20: סה"כ | B20: =SUM(B17:B19) | C20: =SUM(C17:C19) | D20: =SUM(D17:D19) | E20: =SUM(E17:E19) | F20: =SUM(F17:F19) | G20: =SUM(G17:G19)
A22: הכנסת מדינה עתידית ממס הכנסה+רווחי הון, 2065 — בהנחת מס ממוצע קבוע כמו 2022 (₪ לחודש)
A23: קבוצת אוכלוסייה | B23: חמישון 1 | C23: חמישון 2 | D23: חמישון 3 | E23: חמישון 4 | F23: חמישון 5 | G23: סה"כ
A24: יהודים לא חרדים | B24: =B17*1000*'בסיס 2022'!B13 | C24: =C17*1000*'בסיס 2022'!C13 | D24: =D17*1000*'בסיס 2022'!D13 | E24: =E17*1000*'בסיס 2022'!E13 | F24: =F17*1000*'בסיס 2022'!F13 | G24: =SUM(B24:F24)
A25: חרדים | B25: =B18*1000*'בסיס 2022'!B14 | C25: =C18*1000*'בסיס 2022'!C14 | D25: =D18*1000*'בסיס 2022'!D14 | E25: =E18*1000*'בסיס 2022'!E14 | F25: =F18*1000*'בסיס 2022'!F14 | G25: =SUM(B25:F25)
A26: ערבים | B26: =B19*1000*'בסיס 2022'!B15 | C26: =C19*1000*'בסיס 2022'!C15 | D26: =D19*1000*'בסיס 2022'!D15 | E26: =E19*1000*'בסיס 2022'!E15 | F26: =F19*1000*'בסיס 2022'!F15 | G26: =SUM(B26:F26)
A27: סה"כ | B27: =SUM(B24:B26) | C27: =SUM(C24:C26) | D27: =SUM(D24:D26) | E27: =SUM(E24:E26) | F27: =SUM(F24:F26) | G27: =SUM(G24:G26)
A29: השוואה להיום — נטרול אפקט גידול האוכלוסייה (ממוצע למשק בית, לא סך הכל)
A30: מס הכנסה ממוצע למשק בית, 2022 (₪ לחודש) — נטל הבסיס שמושווים אליו | B30: ='בסיס 2022'!B44
A31: מס הכנסה ממוצע למשק בית, 2065 'ללא שינוי מדיניות' (₪ לחודש) | B31: =G27/(G20*1000)
A32: הפער בנטל הממוצע למשק"ב (%) — זהו אפקט שינוי התמהיל בלבד, מנוטרל מגידול האוכלוסייה | B32: =B31/B30-1
A34: לשם השוואה בלבד — בערכים נומינליים (כולל את אפקט גידול האוכלוסייה)
A35: הכנסת המדינה הכוללת, 2022 (₪ לחודש, בפועל) | B35: ='בסיס 2022'!G22
A36: הכנסת המדינה הכוללת, 2065 'ללא שינוי מדיניות' (₪ לחודש) | B36: =G27
A37: שינוי נומינלי (%) — עולה חרף ירידת הממוצע למשק"ב, כי האוכלוסייה גדלה | B37: =B36/B35-1
A39: חלק חמישון 5 (העליון) מסך נטל מס ההכנסה, 2022 | B39: ='בסיס 2022'!F32
A40: חלק חמישון 5 מסך הנטל, 2065 'ללא שינוי מדיניות' | B40: =F27/G27
A42: כדי לשמור על אותו נטל מס ממוצע למשק"ב כמו היום (מבודד מגידול האוכלוסייה) — שלוש חלופות
A44: יעד הכנסה כוללת 2065 — לו נשמר הנטל הממוצע למשק"ב כמו 2022, על אוכלוסיית 2065 הגדולה יותר (₪ לחודש) | B44: =B30*B6*1000
A45: הכנסה בפועל 2065 'ללא שינוי מדיניות' (₪ לחודש) | B45: =G27
A46: פער מהיעד (₪ לחודש) | B46: =B44-B45
A48: א. העלאה אחידה (%) על תשלום המס הממוצע בכל התאים (כל קבוצה וחמישון)
A49: שיעור ההעלאה הנדרש | B49: =B44/B45-1
A50: משמעות: התפלגות הנטל בין החמישונים לא משתנה — עדיין | B50: =F27/G27
...

Sheet השוואת תרחישים
A1: השוואת תרחישים: אפקט שינוי התמהיל על נטל המס, מנוטרל מגידול האוכלוסייה
A2: כל שורה: תרחיש דמוגרפי + שנת אופק. הפער העיקרי (העמודות המודגשות) הוא מול יעד שגדל עם האוכלוסייה אך שומר על נטל המס הממוצע למשק"ב כמו 2022 — כך שהוא מבודד את אפקט שינוי התמהיל בלבד. כל התאים הם נוסחאות המבוססות על הגיליונות 'בסיס 2022' ו'תחזית הרכב אוכלוסייה'.
A4: תרחיש | B4: שנה | C4: מדד גידול משקי"ב | D4: חלק יל"ח | E4: חלק חרדים | F4: חלק ערבים | G4: סה"כ משקי בית עתידי (אלפים) | H4: הכנסה עתידית בפועל ללא שינוי (₪/חודש) | I4: הכנסת חמישון 5 ללא שינוי (₪/חודש) | J4: יעד הכנסה — נטל ממוצע כמו 2022 (₪/חודש) | K4: פער מהיעד (₪/חודש) | L4: פער מהיעד (%) – אפקט תמהיל נטו | M4: לשם השוואה: שינוי נומינלי מול 2022 (%) | N4: העלאה אחידה נדרשת לסגירת הפער (%) | O4: העלאה על חמישון 5 בלבד לסגירה (%) | P4: חלק חמישון 5 בנטל – ללא שינוי | Q4: חלק חמישון 5 בנטל – הוא סופג הפער
A5: גבוה | B5: 2025 | C5: ='תחזית הרכב אוכלוסייה'!C48 | D5: ='תחזית הרכב אוכלוסייה'!C7 | E5: ='תחזית הרכב אוכלוסייה'!E7 | F5: ='תחזית הרכב אוכלוסייה'!D7 | G5: ='בסיס 2022'!$G$9*C5 | H5: =G5*1000*(D5*'בסיס 2022'!$B$39+E5*'בסיס 2022'!$B$40+F5*'בסיס 2022'!$B$41) | I5: =G5*1000*(D5*'בסיס 2022'!$C$39+E5*'בסיס 2022'!$C$40+F5*'בסיס 2022'!$C$41) | J5: =G5*1000*'בסיס 2022'!$B$44 | K5: =J5-H5 | L5: =H5/J5-1 | M5: =H5/'בסיס 2022'!$G$22-1 | N5: =J5/H5-1 | O5: =K5/I5 | P5: =I5/H5 | Q5: =(I5+K5)/J5
A6: גבוה | B6: 2035 | C6: ='תחזית הרכב אוכלוסייה'!D48 | D6: ='תחזית הרכב אוכלוסייה'!C8 | E6: ='תחזית הרכב אוכלוסייה'!E8 | F6: ='תחזית הרכב אוכלוסייה'!D8 | G6: ='בסיס 2022'!$G$9*C6 | H6: =G6*1000*(D6*'בסיס 2022'!$B$39+E6*'בסיס 2022'!$B$40+F6*'בסיס 2022'!$B$41) | I6: =G6*1000*(D6*'בסיס 2022'!$C$39+E6*'בסיס 2022'!$C$40+F6*'בסיס 2022'!$C$41) | J6: =G6*1000*'בסיס 2022'!$B$44 | K6: =J6-H6 | L6: =H6/J6-1 | M6: =H6/'בסיס 2022'!$G$22-1 | N6: =J6/H6-1 | O6: =K6/I6 | P6: =I6/H6 | Q6: =(I6+K6)/J6
A7: גבוה | B7: 2045 | C7: ='תחזית הרכב אוכלוסייה'!E48 | D7: ='תחזית הרכב אוכלוסייה'!C9 | E7: ='תחזית הרכב אוכלוסייה'!E9 | F7: ='תחזית הרכב אוכלוסייה'!D9 | G7: ='בסיס 2022'!$G$9*C7 | H7: =G7*1000*(D7*'בסיס 2022'!$B$39+E7*'בסיס 2022'!$B$40+F7*'בסיס 2022'!$B$41) | I7: =G7*1000*(D7*'בסיס 2022'!$C$39+E7*'בסיס 2022'!$C$40+F7*'בסיס 2022'!$C$41) | J7: =G7*1000*'בסיס 2022'!$B$44 | K7: =J7-H7 | L7: =H7/J7-1 | M7: =H7/'בסיס 2022'!$G$22-1 | N7: =J7/H7-1 | O7: =K7/I7 | P7: =I7/H7 | Q7: =(I7+K7)/J7
A8: גבוה | B8: 2055 | C8: ='תחזית הרכב אוכלוסייה'!F48 | D8: ='תחזית הרכב אוכלוסייה'!C10 | E8: ='תחזית הרכב אוכלוסייה'!E10 | F8: ='תחזית הרכב אוכלוסייה'!D10 | G8: ='בסיס 2022'!$G$9*C8 | H8: =G8*1000*(D8*'בסיס 2022'!$B$39+E8*'בסיס 2022'!$B$40+F8*'בסיס 2022'!$B$41) | I8: =G8*1000*(D8*'בסיס 2022'!$C$39+E8*'בסיס 2022'!$C$40+F8*'בסיס 2022'!$C$41) | J8: =G8*1000*'בסיס 2022'!$B$44 | K8: =J8-H8 | L8: =H8/J8-1 | M8: =H8/'בסיס 2022'!$G$22-1 | N8: =J8/H8-1 | O8: =K8/I8 | P8: =I8/H8 | Q8: =(I8+K8)/J8
A9: גבוה | B9: 2065 | C9: ='תחזית הרכב אוכלוסייה'!G48 | D9: ='תחזית הרכב אוכלוסייה'!C11 | E9: ='תחזית הרכב אוכלוסייה'!E11 | F9: ='תחזית הרכב אוכלוסייה'!D11 | G9: ='בסיס 2022'!$G$9*C9 | H9: =G9*1000*(D9*'בסיס 2022'!$B$39+E9*'בסיס 2022'!$B$40+F9*'בסיס 2022'!$B$41) | I9: =G9*1000*(D9*'בסיס 2022'!$C$39+E9*'בסיס 2022'!$C$40+F9*'בסיס 2022'!$C$41) | J9: =G9*1000*'בסיס 2022'!$B$44 | K9: =J9-H9 | L9: =H9/J9-1 | M9: =H9/'בסיס 2022'!$G$22-1 | N9: =J9/H9-1 | O9: =K9/I9 | P9: =I9/H9 | Q9: =(I9+K9)/J9
A11: ריאלי | B11: 2025 | C11: ='תחזית הרכב אוכלוסייה'!C49 | D11: ='תחזית הרכב אוכלוסייה'!C14 | E11: ='תחזית הרכב אוכלוסייה'!E14 | F11: ='תחזית הרכב אוכלוסייה'!D14 | G11: ='בסיס 2022'!$G$9*C11 | H11: =G11*1000*(D11*'בסיס 2022'!$B$39+E11*'בסיס 2022'!$B$40+F11*'בסיס 2022'!$B$41) | I11: =G11*1000*(D11*'בסיס 2022'!$C$39+E11*'בסיס 2022'!$C$40+F11*'בסיס 2022'!$C$41) | J11: =G11*1000*'בסיס 2022'!$B$44 | K11: =J11-H11 | L11: =H11/J11-1 | M11: =H11/'בסיס 2022'!$G$22-1 | N11: =J11/H11-1 | O11: =K11/I11 | P11: =I11/H11 | Q11: =(I11+K11)/J11
A12: ריאלי | B12: 2035 | C12: ='תחזית הרכב אוכלוסייה'!D49 | D12: ='תחזית הרכב אוכלוסייה'!C15 | E12: ='תחזית הרכב אוכלוסייה'!E15 | F12: ='תחזית הרכב אוכלוסייה'!D15 | G12: ='בסיס 2022'!$G$9*C12 | H12: =G12*1000*(D12*'בסיס 2022'!$B$39+E12*'בסיס 2022'!$B$40+F12*'בסיס 2022'!$B$41) | I12: =G12*1000*(D12*'בסיס 2022'!$C$39+E12*'בסיס 2022'!$C$40+F12*'בסיס 2022'!$C$41) | J12: =G12*1000*'בסיס 2022'!$B$44 | K12: =J12-H12 | L12: =H12/J12-1 | M12: =H12/'בסיס 2022'!$G$22-1 | N12: =J12/H12-1 | O12: =K12/I12 | P12: =I12/H12 | Q12: =(I12+K12)/J12
A13: ריאלי | B13: 2045 | C13: ='תחזית הרכב אוכלוסייה'!E49 | D13: ='תחזית הרכב אוכלוסייה'!C16 | E13: ='תחזית הרכב אוכלוסייה'!E16 | F13: ='תחזית הרכב אוכלוסייה'!D16 | G13: ='בסיס 2022'!$G$9*C13 | H13: =G13*1000*(D13*'בסיס 2022'!$B$39+E13*'בסיס 2022'!$B$40+F13*'בסיס 2022'!$B$41) | I13: =G13*1000*(D13*'בסיס 2022'!$C$39+E13*'בסיס 2022'!$C$40+F13*'בסיס 2022'!$C$41) | J13: =G13*1000*'בסיס 2022'!$B$44 | K13: =J13-H13 | L13: =H13/J13-1 | M13: =H13/'בסיס 2022'!$G$22-1 | N13: =J13/H13-1 | O13: =K13/I13 | P13: =I13/H13 | Q13: =(I13+K13)/J13
A14: ריאלי | B14: 2055 | C14: ='תחזית הרכב אוכלוסייה'!F49 | D14: ='תחזית הרכב אוכלוסייה'!C17 | E14: ='תחזית הרכב אוכלוסייה'!E17 | F14: ='תחזית הרכב אוכלוסייה'!D17 | G14: ='בסיס 2022'!$G$9*C14 | H14: =G14*1000*(D14*'בסיס 2022'!$B$39+E14*'בסיס 2022'!$B$40+F14*'בסיס 2022'!$B$41) | I14: =G14*1000*(D14*'בסיס 2022'!$C$39+E14*'בסיס 2022'!$C$40+F14*'בסיס 2022'!$C$41) | J14: =G14*1000*'בסיס 2022'!$B$44 | K14: =J14-H14 | L14: =H14/J14-1 | M14: =H14/'בסיס 2022'!$G$22-1 | N14: =J14/H14-1 | O14: =K14/I14 | P14: =I14/H14 | Q14: =(I14+K14)/J14
A15: ריאלי | B15: 2065 | C15: ='תחזית הרכב אוכלוסייה'!G49 | D15: ='תחזית הרכב אוכלוסייה'!C18 | E15: ='תחזית הרכב אוכלוסייה'!E18 | F15: ='תחזית הרכב אוכלוסייה'!D18 | G15: ='בסיס 2022'!$G$9*C15 | H15: =G15*1000*(D15*'בסיס 2022'!$B$39+E15*'בסיס 2022'!$B$40+F15*'בסיס 2022'!$B$41) | I15: =G15*1000*(D15*'בסיס 2022'!$C$39+E15*'בסיס 2022'!$C$40+F15*'בסיס 2022'!$C$41) | J15: =G15*1000*'בסיס 2022'!$B$44 | K15: =J15-H15 | L15: =H15/J15-1 | M15: =H15/'בסיס 2022'!$G$22-1 | N15: =J15/H15-1 | O15: =K15/I15 | P15: =I15/H15 | Q15: =(I15+K15)/J15
A17: נמוך | B17: 2025 | C17: ='תחזית הרכב אוכלוסייה'!C50 | D17: ='תחזית הרכב אוכלוסייה'!C21 | E17: ='תחזית הרכב אוכלוסייה'!E21 | F17: ='תחזית הרכב אוכלוסייה'!D21 | G17: ='בסיס 2022'!$G$9*C17 | H17: =G17*1000*(D17*'בסיס 2022'!$B$39+E17*'בסיס 2022'!$B$40+F17*'בסיס 2022'!$B$41) | I17: =G17*1000*(D17*'בסיס 2022'!$C$39+E17*'בסיס 2022'!$C$40+F17*'בסיס 2022'!$C$41) | J17: =G17*1000*'בסיס 2022'!$B$44 | K17: =J17-H17 | L17: =H17/J17-1 | M17: =H17/'בסיס 2022'!$G$22-1 | N17: =J17/H17-1 | O17: =K17/I17 | P17: =I17/H17 | Q17: =(I17+K17)/J17
A18: נמוך | B18: 2035 | C18: ='תחזית הרכב אוכלוסייה'!D50 | D18: ='תחזית הרכב אוכלוסייה'!C22 | E18: ='תחזית הרכב אוכלוסייה'!E22 | F18: ='תחזית הרכב אוכלוסייה'!D22 | G18: ='בסיס 2022'!$G$9*C18 | H18: =G18*1000*(D18*'בסיס 2022'!$B$39+E18*'בסיס 2022'!$B$40+F18*'בסיס 2022'!$B$41) | I18: =G18*1000*(D18*'בסיס 2022'!$C$39+E18*'בסיס 2022'!$C$40+F18*'בסיס 2022'!$C$41) | J18: =G18*1000*'בסיס 2022'!$B$44 | K18: =J18-H18 | L18: =H18/J18-1 | M18: =H18/'בסיס 2022'!$G$22-1 | N18: =J18/H18-1 | O18: =K18/I18 | P18: =I18/H18 | Q18: =(I18+K18)/J18
A19: נמוך | B19: 2045 | C19: ='תחזית הרכב אוכלוסייה'!E50 | D19: ='תחזית הרכב אוכלוסייה'!C23 | E19: ='תחזית הרכב אוכלוסייה'!E23 | F19: ='תחזית הרכב אוכלוסייה'!D23 | G19: ='בסיס 2022'!$G$9*C19 | H19: =G19*1000*(D19*'בסיס 2022'!$B$39+E19*'בסיס 2022'!$B$40+F19*'בסיס 2022'!$B$41) | I19: =G19*1000*(D19*'בסיס 2022'!$C$39+E19*'בסיס 2022'!$C$40+F19*'בסיס 2022'!$C$41) | J19: =G19*1000*'בסיס 2022'!$B$44 | K19: =J19-H19 | L19: =H19/J19-1 | M19: =H19/'בסיס 2022'!$G$22-1 | N19: =J19/H19-1 | O19: =K19/I19 | P19: =I19/H19 | Q19: =(I19+K19)/J19
A20: נמוך | B20: 2055 | C20: ='תחזית הרכב אוכלוסייה'!F50 | D20: ='תחזית הרכב אוכלוסייה'!C24 | E20: ='תחזית הרכב אוכלוסייה'!E24 | F20: ='תחזית הרכב אוכלוסייה'!D24 | G20: ='בסיס 2022'!$G$9*C20 | H20: =G20*1000*(D20*'בסיס 2022'!$B$39+E20*'בסיס 2022'!$B$40+F20*'בסיס 2022'!$B$41) | I20: =G20*1000*(D20*'בסיס 2022'!$C$39+E20*'בסיס 2022'!$C$40+F20*'בסיס 2022'!$C$41) | J20: =G20*1000*'בסיס 2022'!$B$44 | K20: =J20-H20 | L20: =H20/J20-1 | M20: =H20/'בסיס 2022'!$G$22-1 | N20: =J20/H20-1 | O20: =K20/I20 | P20: =I20/H20 | Q20: =(I20+K20)/J20
A21: נמוך | B21: 2065 | C21: ='תחזית הרכב אוכלוסייה'!G50 | D21: ='תחזית הרכב אוכלוסייה'!C25 | E21: ='תחזית הרכב אוכלוסייה'!E25 | F21: ='תחזית הרכב אוכלוסייה'!D25 | G21: ='בסיס 2022'!$G$9*C21 | H21: =G21*1000*(D21*'בסיס 2022'!$B$39+E21*'בסיס 2022'!$B$40+F21*'בסיס 2022'!$B$41) | I21: =G21*1000*(D21*'בסיס 2022'!$C$39+E21*'בסיס 2022'!$C$40+F21*'בסיס 2022'!$C$41) | J21: =G21*1000*'בסיס 2022'!$B$44 | K21: =J21-H21 | L21: =H21/J21-1 | M21: =H21/'בסיס 2022'!$G$22-1 | N21: =J21/H21-1 | O21: =K21/I21 | P21: =I21/H21 | Q21: =(I21+K21)/J21

Sheet גרפים
A1: גרפים
A3: נתוני עזר לגרף 1: הרכב האוכלוסייה לאורך זמן (תרחיש ריאלי)
A4: שנה | B4: יהודים לא חרדים | C4: חרדים | D4: ערבים
A5: ='תחזית הרכב אוכלוסייה'!B13 | B5: ='תחזית הרכב אוכלוסייה'!C13 | C5: ='תחזית הרכב אוכלוסייה'!E13 | D5: ='תחזית הרכב אוכלוסייה'!D13
A6: ='תחזית הרכב אוכלוסייה'!B14 | B6: ='תחזית הרכב אוכלוסייה'!C14 | C6: ='תחזית הרכב אוכלוסייה'!E14 | D6: ='תחזית הרכב אוכלוסייה'!D14
A7: ='תחזית הרכב אוכלוסייה'!B15 | B7: ='תחזית הרכב אוכלוסייה'!C15 | C7: ='תחזית הרכב אוכלוסייה'!E15 | D7: ='תחזית הרכב אוכלוסייה'!D15
A8: ='תחזית הרכב אוכלוסייה'!B16 | B8: ='תחזית הרכב אוכלוסייה'!C16 | C8: ='תחזית הרכב אוכלוסייה'!E16 | D8: ='תחזית הרכב אוכלוסייה'!D16
A9: ='תחזית הרכב אוכלוסייה'!B17 | B9: ='תחזית הרכב אוכלוסייה'!C17 | C9: ='תחזית הרכב אוכלוסייה'!E17 | D9: ='תחזית הרכב אוכלוסייה'!D17
A10: ='תחזית הרכב אוכלוסייה'!B18 | B10: ='תחזית הרכב אוכלוסייה'!C18 | C10: ='תחזית הרכב אוכלוסייה'!E18 | D10: ='תחזית הרכב אוכלוסייה'!D18
A13: נתוני עזר לגרף 2: הכנסת המדינה ממס הכנסה לפי חמישון — 2022 מול 2065 (תרחיש ריאלי)
B14: חמישון 1 | C14: חמישון 2 | D14: חמישון 3 | E14: חמישון 4 | F14: חמישון 5
A15: 2022 (בפועל) | B15: ='בסיס 2022'!B22 | C15: ='בסיס 2022'!C22 | D15: ='בסיס 2022'!D22 | E15: ='בסיס 2022'!E22 | F15: ='בסיס 2022'!F22
A16: 2065 – ללא שינוי מדיניות | B16: ='פירוט תרחיש ריאלי 2065'!B27 | C16: ='פירוט תרחיש ריאלי 2065'!C27 | D16: ='פירוט תרחיש ריאלי 2065'!D27 | E16: ='פירוט תרחיש ריאלי 2065'!E27 | F16: ='פירוט תרחיש ריאלי 2065'!F27
A17: 2065 – חמישון 5 סופג את כל הפער מהיעד | B17: ='פירוט תרחיש ריאלי 2065'!B27 | C17: ='פירוט תרחיש ריאלי 2065'!C27 | D17: ='פירוט תרחיש ריאלי 2065'!D27 | E17: ='פירוט תרחיש ריאלי 2065'!E27 | F17: ='פירוט תרחיש ריאלי 2065'!B59
